Workbook

Sheet Dashboard
A1: Chirala Bay Resort PMS — Development Control Dashboard
A2: Scope: 130 planned screens | 120 screen designs completed | Development tracking starts at Not Started | Update the Screen Requirements sheet to drive this dashboard
A4: Total Screens | D4: Designs Completed | G4: Development Done | J4: Overall Progress
A5: =COUNTA('Screen Requirements'!$B$5:$B$134) | D5: =COUNTIF('Screen Requirements'!$C$5:$C$134,"Completed") | G5: =COUNTIF('Screen Requirements'!$N$5:$N$134,"Done") | J5: =AVERAGE('Screen Requirements'!$O$5:$O$134)
A8: Module Progress | G8: Delivery Sequence | H8: Delivery Sequence | I8: Delivery Sequence | J8: Delivery Sequence | K8: Delivery Sequence | L8: Delivery Sequence
A9: Module | B9: Screens | C9: Done | D9: Average Progress | F9: Phase | G9: Phase Name | H9: Sprint(s) | I9: Weeks | J9: Screens | K9: Status | L9: Progress
A10: Overview | B10: =COUNTIF('Screen Requirements'!$D$5:$D$134,A10) | C10: =COUNTIFS('Screen Requirements'!$D$5:$D$134,A10,'Screen Requirements'!$N$5:$N$134,"Done") | D10: =IF(B10=0,0,SUMIF('Screen Requirements'!$D$5:$D$134,A10,'Screen Requirements'!$O$5:$O$134)/B10) | F10: 1 | G10: Core Platform, Security & Masters | H10: S01-S02 | I10: 4 | J10: 15 | K10: ='Development Plan'!L5 | L10: ='Development Plan'!M5
A11: Front Desk | B11: =COUNTIF('Screen Requirements'!$D$5:$D$134,A11) | C11: =COUNTIFS('Screen Requirements'!$D$5:$D$134,A11,'Screen Requirements'!$N$5:$N$134,"Done") | D11: =IF(B11=0,0,SUMIF('Screen Requirements'!$D$5:$D$134,A11,'Screen Requirements'!$O$5:$O$134)/B11) | F11: 2 | G11: Inventory, Rates & Distribution Foundation | H11: S03-S04 | I11: 4 | J11: 11 | K11: ='Development Plan'!L6 | L11: ='Development Plan'!M6
A12: Reservations | B12: =COUNTIF('Screen Requirements'!$D$5:$D$134,A12) | C12: =COUNTIFS('Screen Requirements'!$D$5:$D$134,A12,'Screen Requirements'!$N$5:$N$134,"Done") | D12: =IF(B12=0,0,SUMIF('Screen Requirements'!$D$5:$D$134,A12,'Screen Requirements'!$O$5:$O$134)/B12) | F12: 3 | G12: Reservations, Groups & Front Desk | H12: S05-S07 | I12: 6 | J12: 21 | K12: ='Development Plan'!L7 | L12: ='Development Plan'!M7
A13: Housekeeping | B13: =COUNTIF('Screen Requirements'!$D$5:$D$134,A13) | C13: =COUNTIFS('Screen Requirements'!$D$5:$D$134,A13,'Screen Requirements'!$N$5:$N$134,"Done") | D13: =IF(B13=0,0,SUMIF('Screen Requirements'!$D$5:$D$134,A13,'Screen Requirements'!$O$5:$O$134)/B13) | F13: 4 | G13: Guest CRM, Privacy & Communications | H13: S08-S09 | I13: 4 | J13: 11 | K13: ='Development Plan'!L8 | L13: ='Development Plan'!M8
A14: Property & Rooms | B14: =COUNTIF('Screen Requirements'!$D$5:$D$134,A14) | C14: =COUNTIFS('Screen Requirements'!$D$5:$D$134,A14,'Screen Requirements'!$N$5:$N$134,"Done") | D14: =IF(B14=0,0,SUMIF('Screen Requirements'!$D$5:$D$134,A14,'Screen Requirements'!$O$5:$O$134)/B14) | F14: 5 | G14: Housekeeping & Guest Services | H14: S10-S11 | I14: 4 | J14: 8 | K14: ='Development Plan'!L9 | L14: ='Development Plan'!M9
A15: Guest CRM | B15: =COUNTIF('Screen Requirements'!$D$5:$D$134,A15) | C15: =COUNTIFS('Screen Requirements'!$D$5:$D$134,A15,'Screen Requirements'!$N$5:$N$134,"Done") | D15: =IF(B15=0,0,SUMIF('Screen Requirements'!$D$5:$D$134,A15,'Screen Requirements'!$O$5:$O$134)/B15) | F15: 6 | G15: Restaurant POS & Kitchen | H15: S12-S13 | I15: 4 | J15: 9 | K15: ='Development Plan'!L10 | L15: ='Development Plan'!M10
A16: Food & Beverage | B16: =COUNTIF('Screen Requirements'!$D$5:$D$134,A16) | C16: =COUNTIFS('Screen Requirements'!$D$5:$D$134,A16,'Screen Requirements'!$N$5:$N$134,"Done") | D16: =IF(B16=0,0,SUMIF('Screen Requirements'!$D$5:$D$134,A16,'Screen Requirements'!$O$5:$O$134)/B16) | F16: 7 | G16: Inventory & Procurement | H16: S14-S15 | I16: 4 | J16: 10 | K16: ='Development Plan'!L11 | L16: ='Development Plan'!M11
A17: Guest Services | B17: =COUNTIF('Screen Requirements'!$D$5:$D$134,A17) | C17: =COUNTIFS('Screen Requirements'!$D$5:$D$134,A17,'Screen Requirements'!$N$5:$N$134,"Done") | D17: =IF(B17=0,0,SUMIF('Screen Requirements'!$D$5:$D$134,A17,'Screen Requirements'!$O$5:$O$134)/B17) | F17: 8 | G17: Maintenance & Asset Operations | H17: S16 | I17: 2 | J17: 6 | K17: ='Development Plan'!L12 | L17: ='Development Plan'!M12
A18: Activities | B18: =COUNTIF('Screen Requirements'!$D$5:$D$134,A18) | C18: =COUNTIFS('Screen Requirements'!$D$5:$D$134,A18,'Screen Requirements'!$N$5:$N$134,"Done") | D18: =IF(B18=0,0,SUMIF('Screen Requirements'!$D$5:$D$134,A18,'Screen Requirements'!$O$5:$O$134)/B18) | F18: 9 | G18: Activities, Spa, Events & Transport | H18: S17-S19 | I18: 6 | J18: 17 | K18: ='Development Plan'!L13 | L18: ='Development Plan'!M13
A19: Spa | B19: =COUNTIF('Screen Requirements'!$D$5:$D$134,A19) | C19: =COUNTIFS('Screen Requirements'!$D$5:$D$134,A19,'Screen Requirements'!$N$5:$N$134,"Done") | D19: =IF(B19=0,0,SUMIF('Screen Requirements'!$D$5:$D$134,A19,'Screen Requirements'!$O$5:$O$134)/B19) | F19: 10 | G19: Workforce, Finance & Analytics | H19: S20-S22 | I19: 6 | J19: 10 | K19: ='Development Plan'!L14 | L19: ='Development Plan'!M14
A20: Events & Banquets | B20: =COUNTIF('Screen Requirements'!$D$5:$D$134,A20) | C20: =COUNTIFS('Screen Requirements'!$D$5:$D$134,A20,'Screen Requirements'!$N$5:$N$134,"Done") | D20: =IF(B20=0,0,SUMIF('Screen Requirements'!$D$5:$D$134,A20,'Screen Requirements'!$O$5:$O$134)/B20) | F20: 11 | G20: Portals, Integrations & AI | H20: S23-S25 | I20: 6 | J20: 11 | K20: ='Development Plan'!L15 | L20: ='Development Plan'!M15
A21: Transport | B21: =COUNTIF('Screen Requirements'!$D$5:$D$134,A21) | C21: =COUNTIFS('Screen Requirements'!$D$5:$D$134,A21,'Screen Requirements'!$N$5:$N$134,"Done") | D21: =IF(B21=0,0,SUMIF('Screen Requirements'!$D$5:$D$134,A21,'Screen Requirements'!$O$5:$O$134)/B21) | F21: 12 | G21: Executive Dashboard, UAT & Release | H21: S26-S27 | I21: 4 | J21: 1 | K21: ='Development Plan'!L16 | L21: ='Development Plan'!M16
A22: Maintenance | B22: =COUNTIF('Screen Requirements'!$D$5:$D$134,A22) | C22: =COUNTIFS('Screen Requirements'!$D$5:$D$134,A22,'Screen Requirements'!$N$5:$N$134,"Done") | D22: =IF(B22=0,0,SUMIF('Screen Requirements'!$D$5:$D$134,A22,'Screen Requirements'!$O$5:$O$134)/B22)
A23: Inventory | B23: =COUNTIF('Screen Requirements'!$D$5:$D$134,A23) | C23: =COUNTIFS('Screen Requirements'!$D$5:$D$134,A23,'Screen Requirements'!$N$5:$N$134,"Done") | D23: =IF(B23=0,0,SUMIF('Screen Requirements'!$D$5:$D$134,A23,'Screen Requirements'!$O$5:$O$134)/B23)
A24: Workforce | B24: =COUNTIF('Screen Requirements'!$D$5:$D$134,A24) | C24: =COUNTIFS('Screen Requirements'!$D$5:$D$134,A24,'Screen Requirements'!$N$5:$N$134,"Done") | D24: =IF(B24=0,0,SUMIF('Screen Requirements'!$D$5:$D$134,A24,'Screen Requirements'!$O$5:$O$134)/B24)
A25: Finance | B25: =COUNTIF('Screen Requirements'!$D$5:$D$134,A25) | C25: =COUNTIFS('Screen Requirements'!$D$5:$D$134,A25,'Screen Requirements'!$N$5:$N$134,"Done") | D25: =IF(B25=0,0,SUMIF('Screen Requirements'!$D$5:$D$134,A25,'Screen Requirements'!$O$5:$O$134)/B25)
A26: Purchasing | B26: =COUNTIF('Screen Requirements'!$D$5:$D$134,A26) | C26: =COUNTIFS('Screen Requirements'!$D$5:$D$134,A26,'Screen Requirements'!$N$5:$N$134,"Done") | D26: =IF(B26=0,0,SUMIF('Screen Requirements'!$D$5:$D$134,A26,'Screen Requirements'!$O$5:$O$134)/B26)
A27: Distribution | B27: =COUNTIF('Screen Requirements'!$D$5:$D$134,A27) | C27: =COUNTIFS('Screen Requirements'!$D$5:$D$134,A27,'Screen Requirements'!$N$5:$N$134,"Done") | D27: =IF(B27=0,0,SUMIF('Screen Requirements'!$D$5:$D$134,A27,'Screen Requirements'!$O$5:$O$134)/B27)
A28: Administration | B28: =COUNTIF('Screen Requirements'!$D$5:$D$134,A28) | C28: =COUNTIFS('Screen Requirements'!$D$5:$D$134,A28,'Screen Requirements'!$N$5:$N$134,"Done") | D28: =IF(B28=0,0,SUMIF('Screen Requirements'!$D$5:$D$134,A28,'Screen Requirements'!$O$5:$O$134)/B28)
A29: Analytics | B29: =COUNTIF('Screen Requirements'!$D$5:$D$134,A29) | C29: =COUNTIFS('Screen Requirements'!$D$5:$D$134,A29,'Screen Requirements'!$N$5:$N$134,"Done") | D29: =IF(B29=0,0,SUMIF('Screen Requirements'!$D$5:$D$134,A29,'Screen Requirements'!$O$5:$O$134)/B29)
A30: Groups | B30: =COUNTIF('Screen Requirements'!$D$5:$D$134,A30) | C30: =COUNTIFS('Screen Requirements'!$D$5:$D$134,A30,'Screen Requirements'!$N$5:$N$134,"Done") | D30: =IF(B30=0,0,SUMIF('Screen Requirements'!$D$5:$D$134,A30,'Screen Requirements'!$O$5:$O$134)/B30)
A31: Revenue Management | B31: =COUNTIF('Screen Requirements'!$D$5:$D$134,A31) | C31: =COUNTIFS('Screen Requirements'!$D$5:$D$134,A31,'Screen Requirements'!$N$5:$N$134,"Done") | D31: =IF(B31=0,0,SUMIF('Screen Requirements'!$D$5:$D$134,A31,'Screen Requirements'!$O$5:$O$134)/B31)
A32: AI & Automation | B32: =COUNTIF('Screen Requirements'!$D$5:$D$134,A32) | C32: =COUNTIFS('Screen Requirements'!$D$5:$D$134,A32,'Screen Requirements'!$N$5:$N$134,"Done") | D32: =IF(B32=0,0,SUMIF('Screen Requirements'!$D$5:$D$134,A32,'Screen Requirements'!$O$5:$O$134)/B32)
A33: Communications | B33: =COUNTIF('Screen Requirements'!$D$5:$D$134,A33) | C33: =COUNTIFS('Screen Requirements'!$D$5:$D$134,A33,'Screen Requirements'!$N$5:$N$134,"Done") | D33: =IF(B33=0,0,SUMIF('Screen Requirements'!$D$5:$D$134,A33,'Screen Requirements'!$O$5:$O$134)/B33)
... A37: Integrations | B37: =COUNTIF('Screen Requirements'!$D$5:$D$134,A37) | C37: =COUNTIFS('Screen Requirements'!$D$5:$D$134,A37,'Screen Requirements'!$N$5:$N$134,"Done") | D37: =IF(B37=0,0,SUMIF('Screen Requirements'!$D$5:$D$134,A37,'Screen Requirements'!$O$5:$O$134)/B37)
A40: Priority-Based User Story Backlog
A41: Priority | B41: Stories | C41: Story Points | D41: Completed | E41: Progress
A42: Must Have | B42: =COUNTIF('User Stories & Acceptance'!$T$5:$T$394,A42) | C42: =SUMIF('User Stories & Acceptance'!$T$5:$T$394,A42,'User Stories & Acceptance'!$V$5:$V$394) | D42: =COUNTIFS('User Stories & Acceptance'!$T$5:$T$394,A42,'User Stories & Acceptance'!$X$5:$X$394,"Done") | E42: =IF(B42=0,0,SUMIF('User Stories & Acceptance'!$T$5:$T$394,A42,'User Stories & Acceptance'!$Y$5:$Y$394)/B42)
A43: Should Have | B43: =COUNTIF('User Stories & Acceptance'!$T$5:$T$394,A43) | C43: =SUMIF('User Stories & Acceptance'!$T$5:$T$394,A43,'User Stories & Acceptance'!$V$5:$V$394) | D43: =COUNTIFS('User Stories & Acceptance'!$T$5:$T$394,A43,'User Stories & Acceptance'!$X$5:$X$394,"Done") | E43: =IF(B43=0,0,SUMIF('User Stories & Acceptance'!$T$5:$T$394,A43,'User Stories & Acceptance'!$Y$5:$Y$394)/B43)
A44: Could Have | B44: =COUNTIF('User Stories & Acceptance'!$T$5:$T$394,A44) | C44: =SUMIF('User Stories & Acceptance'!$T$5:$T$394,A44,'User Stories & Acceptance'!$V$5:$V$394) | D44: =COUNTIFS('User Stories & Acceptance'!$T$5:$T$394,A44,'User Stories & Acceptance'!$X$5:$X$394,"Done") | E44: =IF(B44=0,0,SUMIF('User Stories & Acceptance'!$T$5:$T$394,A44,'User Stories & Acceptance'!$Y$5:$Y$394)/B44)

Sheet Module Master
A1: Module Master & Scope Overview
A3: Module ID | B3: Module | C3: Business Objective | D3: Submodules | E3: Primary Roles | F3: Core Data Entities | G3: Key Dependencies | H3: Screen Count | I3: Phase(s)
A4: MOD-01 | B4: Overview | C4: Deliver complete overview capabilities with role-based workflows, validation, auditability and cross-module synchronization. | D4: Operations Control | E4: Owner / GM / Department Heads | F4: dashboard_snapshots, operational_metrics | G4: All operational modules | H4: =COUNTIF('Screen Requirements'!$D$5:$D$134,B4) | I4: 12. Executive Dashboard, UAT & Release
A5: MOD-02 | B5: Front Desk | C5: Deliver complete front desk capabilities with role-based workflows, validation, auditability and cross-module synchronization. | D5: Room Operations, Arrival, Departure & Billing, In-Stay Movement | E5: Front Office Manager / Receptionist / Cashier | F5: stays, room_assignments, folios, keys | G5: Reservations, Rooms, Finance | H5: =COUNTIF('Screen Requirements'!$D$5:$D$134,B5) | I5: 3. Reservations, Groups & Front Desk
A6: MOD-03 | B6: Reservations | C6: Deliver complete reservations capabilities with role-based workflows, validation, auditability and cross-module synchronization. | D6: Availability & Calendar, Booking Creation, Booking Details, Booking Modification, Waitlist & Enquiry, No-Show, Data Quality, Notes & Tasks, Ancillary Sales | E6: Reservation Manager / Agent / Front Desk | F6: reservations, reservation_guests, reservation_items, deposits | G6: Rooms, Rates, Guests, Payments | H6: =COUNTIF('Screen Requirements'!$D$5:$D$134,B6) | I6: 3. Reservations, Groups & Front Desk
A7: MOD-04 | B7: Housekeeping | C7: Deliver complete housekeeping capabilities with role-based workflows, validation, auditability and cross-module synchronization. | D7: Room Operations, Task Management, Room Status, Lost Property, Laundry Operations, Minibar | E7: Housekeeping Manager / Supervisor / Attendant | F7: housekeeping_tasks, room_status_logs, lost_found, linen_movements, minibar_postings | G7: Rooms, Workforce, Inventory | H7: =COUNTIF('Screen Requirements'!$D$5:$D$134,B7) | I7: 5. Housekeeping & Guest Services
A8: MOD-05 | B8: Property & Rooms | C8: Deliver complete property & rooms capabilities with role-based workflows, validation, auditability and cross-module synchronization. | D8: Inventory, Room Details, Room Master, Room Type Master, Property Hierarchy, Amenities Master, Availability Control, Status Audit | E8: Property Admin / Front Office / Housekeeping | F8: properties, buildings, floors, room_types, rooms, amenities | G8: Administration | H8: =COUNTIF('Screen Requirements'!$D$5:$D$134,B8) | I8: 2. Inventory, Rates & Distribution Foundation | 1. Core Platform, Security & Masters
A9: MOD-06 | B9: Guest CRM | C9: Deliver complete guest crm capabilities with role-based workflows, validation, auditability and cross-module synchronization. | D9: Guest 360, Guest Directory, CRM Dashboard, Guest Master, Data Quality, Preferences & Privacy, Identity Verification, Loyalty, Privacy Operations | E9: CRM Manager / Front Desk / Reservations | F9: guests, guest_preferences, consents, documents, loyalty_accounts | G9: Reservations, Communications | H9: =COUNTIF('Screen Requirements'!$D$5:$D$134,B9) | I9: 4. Guest CRM, Privacy & Communications
A10: MOD-07 | B10: Food & Beverage | C10: Deliver complete food & beverage capabilities with role-based workflows, validation, auditability and cross-module synchronization. | D10: Kitchen, Restaurant POS, Restaurant Layout, Order Management, Billing, Controls, Menu Master, Outlet Configuration | E10: F&B Manager / Server / POS Cashier / Kitchen | F10: outlets, tables, menu_items, pos_orders, pos_bills, kitchen_tickets | G10: Inventory, Finance, Guests | H10: =COUNTIF('Screen Requirements'!$D$5:$D$134,B10) | I10: 6. Restaurant POS & Kitchen
A11: MOD-08 | B11: Guest Services | C11: Deliver complete guest services capabilities with role-based workflows, validation, auditability and cross-module synchronization. | D11: Service Desk | E11: Guest Relations / Concierge / Front Desk | F11: service_requests, service_tasks, guest_notes | G11: Guests, Rooms, Workforce | H11: =COUNTIF('Screen Requirements'!$D$5:$D$134,B11) | I11: 5. Housekeeping & Guest Services
A12: MOD-09 | B12: Activities | C12: Deliver complete activities capabilities with role-based workflows, validation, auditability and cross-module synchronization. | D12: Experience Operations, Activity Master, Bookings | E12: Activities Manager / Concierge | F12: activities, activity_slots, activity_bookings | G12: Guests, Resources, Finance | H12: =COUNTIF('Screen Requirements'!$D$5:$D$134,B12) | I12: 9. Activities, Spa, Events & Transport
A13: MOD-10 | B13: Spa | C13: Deliver complete spa capabilities with role-based workflows, validation, auditability and cross-module synchronization. | D13: Appointment Operations, Treatment Master, Resources, Appointments | E13: Spa Manager / Receptionist / Therapist | F13: treatments, spa_resources, spa_appointments | G13: Guests, Workforce, Finance | H13: =COUNTIF('Screen Requirements'!$D$5:$D$134,B13) | I13: 9. Activities, Spa, Events & Transport
A14: MOD-11 | B14: Events & Banquets | C14: Deliver complete events & banquets capabilities with role-based workflows, validation, auditability and cross-module synchronization. | D14: Event Operations, Lead Management, Quotation, Event Execution, Event Modification | E14: Sales / Event Manager / Banquet Operations | F14: event_leads, quotations, events, function_sheets | G14: Guests, Inventory, Finance | H14: =COUNTIF('Screen Requirements'!$D$5:$D$134,B14) | I14: 9. Activities, Spa, Events & Transport
A15: MOD-12 | B15: Transport | C15: Deliver complete transport capabilities with role-based workflows, validation, auditability and cross-module synchronization. | D15: Transfer Operations, Bookings, Fleet, Drivers, Trip Execution | E15: Transport Manager / Dispatcher / Driver | F15: vehicles, drivers, transport_bookings, trips | G15: Guests, Workforce, Finance | H15: =COUNTIF('Screen Requirements'!$D$5:$D$134,B15) | I15: 9. Activities, Spa, Events & Transport
... A31: MOD-28 | B31: Integrations | C31: Deliver complete integrations capabilities with role-based workflows, validation, auditability and cross-module synchronization. | D31: Integration Management | E31: Integration Admin / System Admin | F31: integrations, credentials, webhooks, sync_jobs | G31: All connected services | H31: =COUNTIF('Screen Requirements'!$D$5:$D$134,B31) | I31: 11. Portals, Integrations & AI

Sheet Screen Requirements
A1: Chirala Bay Resort PMS — Screen Requirements & Development Tracker
A2: Editable tracking columns: Development Status, Owner, Planned Start, Planned End and Remarks. Progress updates automatically.
A4: Build Order | B4: Screen ID | C4: Design Status | D4: Module | E4: Submodule | F4: Screen Name | G4: Business Purpose | H4: Functional Requirements | I4: Operations / Actions | J4: Primary Roles | K4: Priority | L4: Development Phase | M4: Sprint | N4: Development Status | O4: Progress % | P4: Dependencies | Q4: Frontend Deliverables | R4: Backend / API | S4: Data Entities | T4: Validation & Business Rules | U4: Acceptance Criteria | V4: Security & Audit | W4: Owner | X4: Planned Start | Y4: Planned End | Z4: Remarks
A5: 130 | B5: SCR-001 | C5: Completed | D5: Overview | E5: Operations Control | F5: Operations Dashboard | G5: Enable overview users to manage operations control through the Operations Dashboard workflow with real-time status, validations and traceability. | H5: Provide role-aware view, filter, search, drill down, export, refresh; support search and filters; validate mandatory fields and business conflicts; persist changes atomically; refresh related availability, balances or task status; record user, timestamp and reason for sensitive changes. | I5: View, filter, search, drill down, export, refresh | J5: Owner / GM / Department Heads | K5: Must Have | L5: 12. Executive Dashboard, UAT & Release | M5: S26-S27 | N5: Not Started | O5: =IF(N5="Done",1,IF(N5="QA",0.9,IF(N5="Integration",0.75,IF(N5="Frontend",0.55,IF(N5="Backend",0.35,IF(N5="UX/UI",0.1,0)))))) | P5: All operational modules | Q5: Responsive desktop/tablet UI; loading, empty, error and permission states; filters; form validation; accessible interactions | R5: GET, POST/PATCH /api/v1/operations-dashboard; lookup, validation and audit endpoints; idempotency for financial/booking writes | S5: dashboard_snapshots, operational_metrics | T5: Tenant/property scope; required fields; optimistic locking; timezone-safe dates; reason mandatory for overrides; valid status transition; linked-record integrity | U5: Authorized users can complete the primary operations dashboard workflow; invalid or conflicting actions are blocked with clear messages; saved changes appear in related screens; sensitive changes are auditable. | V5: RBAC, tenant and property isolation, server-side authorization, audit event for create/update/delete/override
A6: 27 | B6: SCR-002 | C6: Completed | D6: Front Desk | E6: Room Operations | F6: Room Rack | G6: Enable front desk users to manage room operations through the Room Rack workflow with real-time status, validations and traceability. | H6: Provide role-aware list, search, filter, view, create, edit, cancel/delete where allowed, export, audit; support search and filters; validate mandatory fields and business conflicts; persist changes atomically; refresh related availability, balances or task status; record user, timestamp and reason for sensitive changes. | I6: List, search, filter, view, create, edit, cancel/delete where allowed, export, audit | J6: Front Office Manager / Receptionist / Cashier | K6: Must Have | L6: 3. Reservations, Groups & Front Desk | M6: S05-S07 | N6: Not Started | O6: =IF(N6="Done",1,IF(N6="QA",0.9,IF(N6="Integration",0.75,IF(N6="Frontend",0.55,IF(N6="Backend",0.35,IF(N6="UX/UI",0.1,0)))))) | P6: Reservations, Rooms, Finance | Q6: Responsive desktop/tablet UI; loading, empty, error and permission states; filters; form validation; accessible interactions | R6: GET, POST, PUT/PATCH, DELETE /api/v1/room-rack; lookup, validation and audit endpoints; idempotency for financial/booking writes | S6: stays, room_assignments, folios, keys | T6: Tenant/property scope; required fields; optimistic locking; timezone-safe dates; reason mandatory for overrides; availability and overlap check; status-transition rules; cancellation policy | U6: Authorized users can complete the primary room rack workflow; invalid or conflicting actions are blocked with clear messages; saved changes appear in related screens; sensitive changes are auditable. | V6: RBAC, tenant and property isolation, server-side authorization, audit event for create/update/delete/override
A7: 28 | B7: SCR-003 | C7: Completed | D7: Reservations | E7: Availability & Calendar | F7: Reservation Calendar | G7: Enable reservations users to manage availability & calendar through the Reservation Calendar workflow with real-time status, validations and traceability. | H7: Provide role-aware view timeline, filter, create, assign, reschedule, conflict-check, cancel; support search and filters; validate mandatory fields and business conflicts; persist changes atomically; refresh related availability, balances or task status; record user, timestamp and reason for sensitive changes. | I7: View timeline, filter, create, assign, reschedule, conflict-check, cancel | J7: Reservation Manager / Agent / Front Desk | K7: Must Have | L7: 3. Reservations, Groups & Front Desk | M7: S05-S07 | N7: Not Started | O7: =IF(N7="Done",1,IF(N7="QA",0.9,IF(N7="Integration",0.75,IF(N7="Frontend",0.55,IF(N7="Backend",0.35,IF(N7="UX/UI",0.1,0)))))) | P7: Rooms, Rates, Guests, Payments | Q7: Responsive desktop/tablet UI; loading, empty, error and permission states; filters; form validation; accessible interactions | R7: GET, POST, PUT/PATCH, DELETE /api/v1/reservation-calendar; lookup, validation and audit endpoints; idempotency for financial/booking writes | S7: reservations, reservation_guests, reservation_items, deposits | T7: Tenant/property scope; required fields; optimistic locking; timezone-safe dates; reason mandatory for overrides; availability and overlap check; status-transition rules; cancellation policy | U7: Authorized users can complete the primary reservation calendar workflow; invalid or conflicting actions are blocked with clear messages; saved changes appear in related screens; sensitive changes are auditable. | V7: RBAC, tenant and property isolation, server-side authorization, audit event for create/update/delete/override
A8: 29 | B8: SCR-004 | C8: Completed | D8: Reservations | E8: Booking Creation | F8: New Reservation | G8: Enable reservations users to manage booking creation through the New Reservation workflow with real-time status, validations and traceability. | H8: Provide role-aware list, search, filter, view, create, edit, cancel/delete where allowed, export, audit; support search and filters; validate mandatory fields and business conflicts; persist changes atomically; refresh related availability, balances or task status; record user, timestamp and reason for sensitive changes. | I8: List, search, filter, view, create, edit, cancel/delete where allowed, export, audit | J8: Reservation Manager / Agent / Front Desk | K8: Must Have | L8: 3. Reservations, Groups & Front Desk | M8: S05-S07 | N8: Not Started | O8: =IF(N8="Done",1,IF(N8="QA",0.9,IF(N8="Integration",0.75,IF(N8="Frontend",0.55,IF(N8="Backend",0.35,IF(N8="UX/UI",0.1,0)))))) | P8: Rooms, Rates, Guests, Payments | Q8: Responsive desktop/tablet UI; loading, empty, error and permission states; filters; form validation; accessible interactions | R8: GET, POST, PUT/PATCH, DELETE /api/v1/new-reservation; lookup, validation and audit endpoints; idempotency for financial/booking writes | S8: reservations, reservation_guests, reservation_items, deposits | T8: Tenant/property scope; required fields; optimistic locking; timezone-safe dates; reason mandatory for overrides; availability and overlap check; status-transition rules; cancellation policy | U8: Authorized users can complete the primary new reservation workflow; invalid or conflicting actions are blocked with clear messages; saved changes appear in related screens; sensitive changes are auditable. | V8: RBAC, tenant and property isolation, server-side authorization, audit event for create/update/delete/override
A9: 30 | B9: SCR-005 | C9: Completed | D9: Front Desk | E9: Arrival | F9: Guest Check-In | G9: Enable front desk users to manage arrival through the Guest Check-In workflow with real-time status, validations and traceability. | H9: Provide role-aware list, search, filter, view, create, edit, cancel/delete where allowed, export, audit; support search and filters; validate mandatory fields and business conflicts; persist changes atomically; refresh related availability, balances or task status; record user, timestamp and reason for sensitive changes. | I9: List, search, filter, view, create, edit, cancel/delete where allowed, export, audit | J9: Front Office Manager / Receptionist / Cashier | K9: Must Have | L9: 3. Reservations, Groups & Front Desk | M9: S05-S07 | N9: Not Started | O9: =IF(N9="Done",1,IF(N9="QA",0.9,IF(N9="Integration",0.75,IF(N9="Frontend",0.55,IF(N9="Backend",0.35,IF(N9="UX/UI",0.1,0)))))) | P9: Reservations, Rooms, Finance | Q9: Responsive desktop/tablet UI; loading, empty, error and permission states; filters; form validation; accessible interactions | R9: GET, POST, PUT/PATCH, DELETE /api/v1/guest-check-in; lookup, validation and audit endpoints; idempotency for financial/booking writes | S9: stays, room_assignments, folios, keys | T9: Tenant/property scope; required fields; optimistic locking; timezone-safe dates; reason mandatory for overrides; availability and overlap check; status-transition rules; cancellation policy | U9: Authorized users can complete the primary guest check-in workflow; invalid or conflicting actions are blocked with clear messages; saved changes appear in related screens; sensitive changes are auditable. | V9: RBAC, tenant and property isolation, server-side authorization, audit event for create/update/delete/override
A10: 59 | B10: SCR-006 | C10: Completed | D10: Housekeeping | E10: Room Operations | F10: Housekeeping Operations | G10: Enable housekeeping users to manage room operations through the Housekeeping Operations workflow with real-time status, validations and traceability. | H10: Provide role-aware list, search, filter, view, create, edit, cancel/delete where allowed, export, audit; support search and filters; validate mandatory fields and business conflicts; persist changes atomically; refresh related availability, balances or task status; record user, timestamp and reason for sensitive changes. | I10: List, search, filter, view, create, edit, cancel/delete where allowed, export, audit | J10: Housekeeping Manager / Supervisor / Attendant | K10: Should Have | L10: 5. Housekeeping & Guest Services | M10: S10-S11 | N10: Not Started | O10: =IF(N10="Done",1,IF(N10="QA",0.9,IF(N10="Integration",0.75,IF(N10="Frontend",0.55,IF(N10="Backend",0.35,IF(N10="UX/UI",0.1,0)))))) | P10: Rooms, Workforce, Inventory | Q10: Responsive desktop/tablet UI; loading, empty, error and permission states; filters; form validation; accessible interactions | R10: GET, POST, PUT/PATCH, DELETE /api/v1/housekeeping-operations; lookup, validation and audit endpoints; idempotency for financial/booking writes | S10: housekeeping_tasks, room_status_logs, lost_found, linen_movements, minibar_postings | T10: Tenant/property scope; required fields; optimistic locking; timezone-safe dates; reason mandatory for overrides; valid status transition; linked-record integrity | U10: Authorized users can complete the primary housekeeping operations workflow; invalid or conflicting actions are blocked with clear messages; saved changes appear in related screens; sensitive changes are auditable. | V10: RBAC, tenant and property isolation, server-side authorization, audit event for create/update/delete/override
A11: 31 | B11: SCR-007 | C11: Completed | D11: Front Desk | E11: Departure & Billing | F11: Guest Checkout Folio | G11: Enable front desk users to manage departure & billing through the Guest Checkout Folio workflow with real-time status, validations and traceability. | H11: Provide role-aware list, search, filter, view, create, edit, cancel/delete where allowed, export, audit; support search and filters; validate mandatory fields and business conflicts; persist changes atomically; refresh related availability, balances or task status; record user, timestamp and reason for sensitive changes. | I11: List, search, filter, view, create, edit, cancel/delete where allowed, export, audit | J11: Front Office Manager / Receptionist / Cashier | K11: Must Have | L11: 3. Reservations, Groups & Front Desk | M11: S05-S07 | N11: Not Started | O11: =IF(N11="Done",1,IF(N11="QA",0.9,IF(N11="Integration",0.75,IF(N11="Frontend",0.55,IF(N11="Backend",0.35,IF(N11="UX/UI",0.1,0)))))) | P11: Reservations, Rooms, Finance | Q11: Responsive desktop/tablet UI; loading, empty, error and permission states; filters; form validation; accessible interactions | R11: GET, POST, PUT/PATCH, DELETE /api/v1/guest-checkout-folio; lookup, validation and audit endpoints; idempotency for financial/booking writes | S11: stays, room_assignments, folios, keys | T11: Tenant/property scope; required fields; optimistic locking; timezone-safe dates; reason mandatory for overrides; availability and overlap check; status-transition rules; cancellation policy | U11: Authorized users can complete the primary guest checkout folio workflow; invalid or conflicting actions are blocked with clear messages; saved changes appear in related screens; sensitive changes are auditable. | V11: RBAC, tenant and property isolation, server-side authorization, audit event for create/update/delete/override
A12: 16 | B12: SCR-008 | C12: Completed | D12: Property & Rooms | E12: Inventory | F12: Rooms and Villas Inventory | G12: Enable property & rooms users to manage inventory through the Rooms and Villas Inventory workflow with real-time status, validations and traceability. | H12: Provide role-aware list, search, filter, view, create, edit, cancel/delete where allowed, export, audit; support search and filters; validate mandatory fields and business conflicts; persist changes atomically; refresh related availability, balances or task status; record user, timestamp and reason for sensitive changes. | I12: List, search, filter, view, create, edit, cancel/delete where allowed, export, audit | J12: Property Admin / Front Office / Housekeeping | K12: Must Have | L12: 2. Inventory, Rates & Distribution Foundation | M12: S03-S04 | N12: Not Started | O12: =IF(N12="Done",1,IF(N12="QA",0.9,IF(N12="Integration",0.75,IF(N12="Frontend",0.55,IF(N12="Backend",0.35,IF(N12="UX/UI",0.1,0)))))) | P12: Administration | Q12: Responsive desktop/tablet UI; loading, empty, error and permission states; filters; form validation; accessible interactions | R12: GET, POST, PUT/PATCH, DELETE /api/v1/rooms-and-villas-inventory; lookup, validation and audit endpoints; idempotency for financial/booking writes | S12: properties, buildings, floors, room_types, rooms, amenities | T12: Tenant/property scope; required fields; optimistic locking; timezone-safe dates; reason mandatory for overrides; valid status transition; linked-record integrity | U12: Authorized users can complete the primary rooms and villas inventory workflow; invalid or conflicting actions are blocked with clear messages; saved changes appear in related screens; sensitive changes are auditable. | V12: RBAC, tenant and property isolation, server-side authorization, audit event for create/update/delete/override
A13: 48 | B13: SCR-009 | C13: Completed | D13: Guest CRM | E13: Guest 360 | F13: Guest Profile | G13: Enable guest crm users to manage guest 360 through the Guest Profile workflow with real-time status, validations and traceability. | H13: Provide role-aware list, search, filter, view, create, edit, cancel/delete where allowed, export, audit; support search and filters; validate mandatory fields and business conflicts; persist changes atomically; refresh related availability, balances or task status; record user, timestamp and reason for sensitive changes. | I13: List, search, filter, view, create, edit, cancel/delete where allowed, export, audit | J13: CRM Manager / Front Desk / Reservations | K13: Should Have | L13: 4. Guest CRM, Privacy & Communications | M13: S08-S09 | N13: Not Started | O13: =IF(N13="Done",1,IF(N13="QA",0.9,IF(N13="Integration",0.75,IF(N13="Frontend",0.55,IF(N13="Backend",0.35,IF(N13="UX/UI",0.1,0)))))) | P13: Reservations, Communications | Q13: Responsive desktop/tablet UI; loading, empty, error and permission states; filters; form validation; accessible interactions | R13: GET, POST, PUT/PATCH, DELETE /api/v1/guest-profile; lookup, validation and audit endpoints; idempotency for financial/booking writes | S13: guests, guest_preferences, consents, documents, loyalty_accounts | T13: Tenant/property scope; required fields; optimistic locking; timezone-safe dates; reason mandatory for overrides; duplicate detection; consent and retention policy; sensitive document masking | U13: Authorized users can complete the primary guest profile workflow; invalid or conflicting actions are blocked with clear messages; saved changes appear in related screens; sensitive changes are auditable. | V13: RBAC, tenant and property isolation, server-side authorization, audit event for create/update/delete/override; field masking and approval/audit evidence required
A14: 49 | B14: SCR-010 | C14: Completed | D14: Guest CRM | E14: Guest Directory | F14: Guest Directory | G14: Enable guest crm users to manage guest directory through the Guest Directory workflow with real-time status, validations and traceability. | H14: Provide role-aware list, search, filter, view, create, edit, cancel/delete where allowed, export, audit; support search and filters; validate mandatory fields and business conflicts; persist changes atomically; refresh related availability, balances or task status; record user, timestamp and reason for sensitive changes. | I14: List, search, filter, view, create, edit, cancel/delete where allowed, export, audit | J14: CRM Manager / Front Desk / Reservations | K14: Should Have | L14: 4. Guest CRM, Privacy & Communications | M14: S08-S09 | N14: Not Started | O14: =IF(N14="Done",1,IF(N14="QA",0.9,IF(N14="Integration",0.75,IF(N14="Frontend",0.55,IF(N14="Backend",0.35,IF(N14="UX/UI",0.1,0)))))) | P14: Reservations, Communications | Q14: Responsive desktop/tablet UI; loading, empty, error and permission states; filters; form validation; accessible interactions | R14: GET, POST, PUT/PATCH, DELETE /api/v1/guest-directory; lookup, validation and audit endpoints; idempotency for financial/booking writes | S14: guests, guest_preferences, consents, documents, loyalty_accounts | T14: Tenant/property scope; required fields; optimistic locking; timezone-safe dates; reason mandatory for overrides; duplicate detection; consent and retention policy; sensitive document masking | U14: Authorized users can complete the primary guest directory workflow; invalid or conflicting actions are blocked with clear messages; saved changes appear in related screens; sensitive changes are auditable. | V14: RBAC, tenant and property isolation, server-side authorization, audit event for create/update/delete/override; field masking and approval/audit evidence required
A15: 17 | B15: SCR-011 | C15: Completed | D15: Property & Rooms | E15: Room Details | F15: Room Details | G15: Enable property & rooms users to manage room details through the Room Details workflow with real-time status, validations and traceability. | H15: Provide role-aware list, search, filter, view, create, edit, cancel/delete where allowed, export, audit; support search and filters; validate mandatory fields and business conflicts; persist changes atomically; refresh related availability, balances or task status; record user, timestamp and reason for sensitive changes. | I15: List, search, filter, view, create, edit, cancel/delete where allowed, export, audit | J15: Property Admin / Front Office / Housekeeping | K15: Must Have | L15: 2. Inventory, Rates & Distribution Foundation | M15: S03-S04 | N15: Not Started | O15: =IF(N15="Done",1,IF(N15="QA",0.9,IF(N15="Integration",0.75,IF(N15="Frontend",0.55,IF(N15="Backend",0.35,IF(N15="UX/UI",0.1,0)))))) | P15: Administration | Q15: Responsive desktop/tablet UI; loading, empty, error and permission states; filters; form validation; accessible interactions | R15: GET, POST, PUT/PATCH, DELETE /api/v1/room-details; lookup, validation and audit endpoints; idempotency for financial/booking writes | S15: properties, buildings, floors, room_types, rooms, amenities | T15: Tenant/property scope; required fields; optimistic locking; timezone-safe dates; reason mandatory for overrides; valid status transition; linked-record integrity | U15: Authorized users can complete the primary room details workflow; invalid or conflicting actions are blocked with clear messages; saved changes appear in related screens; sensitive changes are auditable. | V15: RBAC, tenant and property isolation, server-side authorization, audit event for create/update/delete/override
A16: 67 | B16: SCR-012 | C16: Completed | D16: Food & Beverage | E16: Kitchen | F16: Kitchen Display System | G16: Enable food & beverage users to manage kitchen through the Kitchen Display System workflow with real-time status, validations and traceability. | H16: Provide role-aware list, search, filter, view, create, edit, cancel/delete where allowed, export, audit; support search and filters; validate mandatory fields and business conflicts; persist changes atomically; refresh related availability, balances or task status; record user, timestamp and reason for sensitive changes. | I16: List, search, filter, view, create, edit, cancel/delete where allowed, export, audit | J16: F&B Manager / Server / POS Cashier / Kitchen | K16: Should Have | L16: 6. Restaurant POS & Kitchen | M16: S12-S13 | N16: Not Started | O16: =IF(N16="Done",1,IF(N16="QA",0.9,IF(N16="Integration",0.75,IF(N16="Frontend",0.55,IF(N16="Backend",0.35,IF(N16="UX/UI",0.1,0)))))) | P16: Inventory, Finance, Guests | Q16: Responsive desktop/tablet UI; loading, empty, error and permission states; filters; form validation; accessible interactions | R16: GET, POST, PUT/PATCH, DELETE /api/v1/kitchen-display-system; lookup, validation and audit endpoints; idempotency for financial/booking writes | S16: outlets, tables, menu_items, pos_orders, pos_bills, kitchen_tickets | T16: Tenant/property scope; required fields; optimistic locking; timezone-safe dates; reason mandatory for overrides; currency precision; tax/rate totals; approval limit; no unbalanced or duplicate posting | U16: Authorized users can complete the primary kitchen display system workflow; invalid or conflicting actions are blocked with clear messages; saved changes appear in related screens; sensitive changes are auditable. | V16: RBAC, tenant and property isolation, server-side authorization, audit event for create/update/delete/override
... A134: 129 | B134: SCR-130 | C134: Pending | D134: Partner Portal | E134: Portal Operations | F134: Portal Booking Management | G134: Enable partner portal users to manage portal operations through the Portal Booking Management workflow with real-time status, validations and traceability. | H134: Provide role-aware list, view, create, edit, activate/deactivate, delete where safe, audit; support search and filters; validate mandatory fields and business conflicts; persist changes atomically; refresh related availability, balances or task status; record user, timestamp and reason for sensitive changes. | I134: List, view, create, edit, activate/deactivate, delete where safe, audit | J134: Travel Agent / Corporate Booker / Sales | K134: Could Have | L134: 11. Portals, Integrations & AI | M134: S23-S25 | N134: Not Started | O134: =IF(N134="Done",1,IF(N134="QA",0.9,IF(N134="Integration",0.75,IF(N134="Frontend",0.55,IF(N134="Backend",0.35,IF(N134="UX/UI",0.1,0)))))) | P134: Reservations, Rates, Finance | Q134: Responsive desktop/tablet UI; loading, empty, error and permission states; filters; form validation; accessible interactions | R134: GET, POST, PUT/PATCH, DELETE /api/v1/portal-booking-management; lookup, validation and audit endpoints; idempotency for financial/booking writes | S134: partner_accounts, portal_bookings, commissions | T134: Tenant/property scope; required fields; optimistic locking; timezone-safe dates; reason mandatory for overrides; valid status transition; linked-record integrity | U134: Authorized users can complete the primary portal booking management workflow; invalid or conflicting actions are blocked with clear messages; saved changes appear in related screens; sensitive changes are auditable. | V134: RBAC, tenant and property isolation, server-side authorization, audit event for create/update/delete/override

Sheet Development Plan
A1: Sequence-Wise Development Plan
A2: Suggested baseline: 1 product owner, 1 UX/UI, 2 frontend, 2 backend, 1 QA, shared DevOps. Dates may be changed after team capacity is confirmed.
A4: Phase | B4: Phase Name | C4: Sprint(s) | D4: Planned Start | E4: Planned End | F4: Duration (Weeks) | G4: Screen Count | H4: Screen IDs | I4: Prerequisite | J4: Main Deliverables | K4: Exit Criteria | L4: Phase Status | M4: Progress %
A5: 1 | B5: Core Platform, Security & Masters | C5: S01-S02 | D5: 46272 | E5: 46299 | F5: 4 | G5: 15 | H5: SCR-026, SCR-039, SCR-040, SCR-041, SCR-042, SCR-043, SCR-059, SCR-060, SCR-061, SCR-062, SCR-063, SCR-064, SCR-123, SCR-125, SCR-126 | I5: Approved architecture, environments and design system | J5: Implement, integrate and test core platform, security & masters screens, APIs, entities, permissions, audit events and reports. | K5: Tenant-safe authentication, RBAC, audit and property masters pass integration tests | L5: Not Started | M5: =IF(L5="Done",1,IF(L5="QA",0.9,IF(L5="Integration",0.75,IF(L5="Frontend",0.55,IF(L5="Backend",0.35,IF(L5="UX/UI",0.1,0))))))
A6: 2 | B6: Inventory, Rates & Distribution Foundation | C6: S03-S04 | D6: 46300 | E6: 46327 | F6: 4 | G6: 11 | H6: SCR-008, SCR-011, SCR-024, SCR-033, SCR-034, SCR-035, SCR-058, SCR-118, SCR-119, SCR-120, SCR-121 | I6: Phase 1 property and permission masters | J6: Implement, integrate and test inventory, rates & distribution foundation screens, APIs, entities, permissions, audit events and reports. | K6: Sellable inventory, rate calculations and restriction rules reconcile | L6: Not Started | M6: =IF(L6="Done",1,IF(L6="QA",0.9,IF(L6="Integration",0.75,IF(L6="Frontend",0.55,IF(L6="Backend",0.35,IF(L6="UX/UI",0.1,0))))))
A7: 3 | B7: Reservations, Groups & Front Desk | C7: S05-S07 | D7: 46328 | E7: 46369 | F7: 6 | G7: 21 | H7: SCR-002, SCR-003, SCR-004, SCR-005, SCR-007, SCR-028, SCR-029, SCR-030, SCR-031, SCR-032, SCR-051, SCR-052, SCR-053, SCR-054, SCR-055, SCR-056, SCR-057, SCR-114, SCR-115, SCR-116, SCR-117 | I7: Availability, rates, taxes and room masters | J7: Implement, integrate and test reservations, groups & front desk screens, APIs, entities, permissions, audit events and reports. | K7: End-to-end book, modify, arrive, in-stay, settle and depart flow passes | L7: Not Started | M7: =IF(L7="Done",1,IF(L7="QA",0.9,IF(L7="Integration",0.75,IF(L7="Frontend",0.55,IF(L7="Backend",0.35,IF(L7="UX/UI",0.1,0))))))
A8: 4 | B8: Guest CRM, Privacy & Communications | C8: S08-S09 | D8: 46370 | E8: 46397 | F8: 4 | G8: 11 | H8: SCR-009, SCR-010, SCR-025, SCR-047, SCR-065, SCR-066, SCR-067, SCR-068, SCR-069, SCR-070, SCR-122 | I8: Guest and reservation identities from Phase 3 | J8: Implement, integrate and test guest crm, privacy & communications screens, APIs, entities, permissions, audit events and reports. | K8: Guest 360, consent, KYC, dedupe and communication journeys pass | L8: Not Started | M8: =IF(L8="Done",1,IF(L8="QA",0.9,IF(L8="Integration",0.75,IF(L8="Frontend",0.55,IF(L8="Backend",0.35,IF(L8="UX/UI",0.1,0))))))
A9: 5 | B9: Housekeeping & Guest Services | C9: S10-S11 | D9: 46398 | E9: 46425 | F9: 4 | G9: 8 | H9: SCR-006, SCR-014, SCR-071, SCR-072, SCR-073, SCR-074, SCR-075, SCR-076 | I9: Rooms, guests and in-house stays | J9: Implement, integrate and test housekeeping & guest services screens, APIs, entities, permissions, audit events and reports. | K9: Room turnaround, service tasks and minibar postings synchronize | L9: Not Started | M9: =IF(L9="Done",1,IF(L9="QA",0.9,IF(L9="Integration",0.75,IF(L9="Frontend",0.55,IF(L9="Backend",0.35,IF(L9="UX/UI",0.1,0))))))
A10: 6 | B10: Restaurant POS & Kitchen | C10: S12-S13 | D10: 46426 | E10: 46453 | F10: 4 | G10: 9 | H10: SCR-012, SCR-013, SCR-077, SCR-078, SCR-079, SCR-080, SCR-081, SCR-082, SCR-083 | I10: Tax, payment, outlets and inventory masters | J10: Implement, integrate and test restaurant pos & kitchen screens, APIs, entities, permissions, audit events and reports. | K10: Order-to-kitchen-to-bill flow and approvals pass | L10: Not Started | M10: =IF(L10="Done",1,IF(L10="QA",0.9,IF(L10="Integration",0.75,IF(L10="Frontend",0.55,IF(L10="Backend",0.35,IF(L10="UX/UI",0.1,0))))))
A11: 7 | B11: Inventory & Procurement | C11: S14-S15 | D11: 46454 | E11: 46481 | F11: 4 | G11: 10 | H11: SCR-020, SCR-023, SCR-102, SCR-103, SCR-104, SCR-105, SCR-106, SCR-107, SCR-108, SCR-109 | I11: Property, finance and user approval setup | J11: Implement, integrate and test inventory & procurement screens, APIs, entities, permissions, audit events and reports. | K11: Requisition-to-PO-to-receipt-to-stock and return flow reconciles | L11: Not Started | M11: =IF(L11="Done",1,IF(L11="QA",0.9,IF(L11="Integration",0.75,IF(L11="Frontend",0.55,IF(L11="Backend",0.35,IF(L11="UX/UI",0.1,0))))))
A12: 8 | B12: Maintenance & Asset Operations | C12: S16 | D12: 46482 | E12: 46495 | F12: 2 | G12: 6 | H12: SCR-019, SCR-097, SCR-098, SCR-099, SCR-100, SCR-101 | I12: Property locations, users and inventory items | J12: Implement, integrate and test maintenance & asset operations screens, APIs, entities, permissions, audit events and reports. | K12: Corrective and preventive work orders update assets and costs | L12: Not Started | M12: =IF(L12="Done",1,IF(L12="QA",0.9,IF(L12="Integration",0.75,IF(L12="Frontend",0.55,IF(L12="Backend",0.35,IF(L12="UX/UI",0.1,0))))))
A13: 9 | B13: Activities, Spa, Events & Transport | C13: S17-S19 | D13: 46496 | E13: 46537 | F13: 6 | G13: 17 | H13: SCR-015, SCR-016, SCR-017, SCR-018, SCR-084, SCR-085, SCR-086, SCR-087, SCR-088, SCR-089, SCR-090, SCR-091, SCR-092, SCR-093, SCR-094, SCR-095, SCR-096 | I13: Guests, payments, resources and notifications | J13: Implement, integrate and test activities, spa, events & transport screens, APIs, entities, permissions, audit events and reports. | K13: Resource-safe booking, service delivery and settlement pass for all outlets | L13: Not Started | M13: =IF(L13="Done",1,IF(L13="QA",0.9,IF(L13="Integration",0.75,IF(L13="Frontend",0.55,IF(L13="Backend",0.35,IF(L13="UX/UI",0.1,0))))))
A14: 10 | B14: Workforce, Finance & Analytics | C14: S20-S22 | D14: 46538 | E14: 46579 | F14: 6 | G14: 10 | H14: SCR-021, SCR-022, SCR-027, SCR-036, SCR-037, SCR-038, SCR-110, SCR-111, SCR-112, SCR-113 | I14: Operational postings and approval hierarchy | J14: Implement, integrate and test workforce, finance & analytics screens, APIs, entities, permissions, audit events and reports. | K14: Roster, attendance, cashiering, audit close, AR and reports reconcile | L14: Not Started | M14: =IF(L14="Done",1,IF(L14="QA",0.9,IF(L14="Integration",0.75,IF(L14="Frontend",0.55,IF(L14="Backend",0.35,IF(L14="UX/UI",0.1,0))))))
A15: 11 | B15: Portals, Integrations & AI | C15: S23-S25 | D15: 46580 | E15: 46621 | F15: 6 | G15: 11 | H15: SCR-044, SCR-045, SCR-046, SCR-048, SCR-049, SCR-050, SCR-124, SCR-127, SCR-128, SCR-129, SCR-130 | I15: Stable APIs, permissions, notification and knowledge policies | J15: Implement, integrate and test portals, integrations & ai screens, APIs, entities, permissions, audit events and reports. | K15: Portal, integration and AI tool calls are secure, observable and accepted | L15: Not Started | M15: =IF(L15="Done",1,IF(L15="QA",0.9,IF(L15="Integration",0.75,IF(L15="Frontend",0.55,IF(L15="Backend",0.35,IF(L15="UX/UI",0.1,0))))))
A16: 12 | B16: Executive Dashboard, UAT & Release | C16: S26-S27 | D16: 46622 | E16: 46649 | F16: 4 | G16: 1 | H16: SCR-001 | I16: All operational modules integrated in staging | J16: Implement, integrate and test executive dashboard, uat & release screens, APIs, entities, permissions, audit events and reports. | K16: KPI reconciliation, security, performance, migration, training and go-live sign-off | L16: Not Started | M16: =IF(L16="Done",1,IF(L16="QA",0.9,IF(L16="Integration",0.75,IF(L16="Frontend",0.55,IF(L16="Backend",0.35,IF(L16="UX/UI",0.1,0))))))

Sheet Role Access Matrix
A1: Role Access Matrix by Module
A2: Permissions: V View, C Create, E Edit, D Delete/Deactivate, A Approve/Override, S Self-service, X No access. Enforce server-side; UI visibility is not authorization.
A4: Role | B4: Overview | C4: Front Desk | D4: Reservations | E4: Housekeeping | F4: Property & Rooms | G4: Guest CRM | H4: Food & Beverage | I4: Guest Services | J4: Activities | K4: Spa | L4: Events & Banquets | M4: Transport | N4: Maintenance | O4: Inventory | P4: Workforce | Q4: Finance | R4: Purchasing | S4: Distribution | T4: Administration | U4: Analytics | V4: Groups | W4: Revenue Management | X4: AI & Automation | Y4: Communications | Z4: Guest Portal | AA4: Partner Portal | AB4: Sales & Marketing | AC4: Integrations
A5: Owner / General Manager | B5: V,A | C5: V,A | D5: V,A | E5: V,A | F5: V,A | G5: V,A | H5: V,A | I5: V,A | J5: V,A | K5: V,A | L5: V,A | M5: V,A | N5: V,A | O5: V,A | P5: V,A | Q5: V,A | R5: V,A | S5: V,A | T5: V,A | U5: V,A | V5: V,A | W5: V,A | X5: V,A | Y5: V,A | Z5: V,A | AA5: V,A | AB5: V,A | AC5: V,A
A6: System Administrator | B6: V | C6: V | D6: V | E6: V | F6: V | G6: V | H6: V | I6: V | J6: V | K6: V | L6: V | M6: V | N6: V | O6: V | P6: V | Q6: V | R6: V | S6: V | T6: V,C,E,D,A | U6: V | V6: V | W6: V | X6: V,C,E,D,A | Y6: V | Z6: V | AA6: V | AB6: V | AC6: V,C,E,D,A
A7: Property Administrator | B7: V | C7: V | D7: V | E7: V | F7: V,C,E,D,A | G7: V | H7: V | I7: V | J7: V | K7: V | L7: V | M7: V | N7: V | O7: V | P7: V | Q7: V | R7: V | S7: V | T7: V,C,E,D,A | U7: V | V7: V | W7: V | X7: V | Y7: V | Z7: V | AA7: V | AB7: V | AC7: V
A8: Front Office Manager | B8: V | C8: V,C,E,D,A | D8: V,C,E,D,A | E8: X | F8: V,C,E,D,A | G8: V,C,E,D,A | H8: X | I8: V,C,E,D,A | J8: X | K8: X | L8: X | M8: X | N8: X | O8: X | P8: X | Q8: V,C,E,D,A | R8: X | S8: X | T8: X | U8: V | V8: V,C,E,D,A | W8: X | X8: X | Y8: X | Z8: X | AA8: X | AB8: X | AC8: X
A9: Receptionist | B9: V | C9: V,C,E,D,A | D9: V,C,E,D,A | E9: X | F9: X | G9: V,C,E,D,A | H9: X | I9: V,C,E,D,A | J9: V,C,E,D,A | K9: V,C,E,D,A | L9: X | M9: V,C,E,D,A | N9: X | O9: X | P9: X | Q9: V,C,E,D,A | R9: X | S9: X | T9: X | U9: V | V9: X | W9: X | X9: X | Y9: X | Z9: X | AA9: X | AB9: X | AC9: X
A10: Reservation Manager / Agent | B10: V | C10: X | D10: V,C,E,D,A | E10: X | F10: X | G10: V,C,E,D,A | H10: X | I10: X | J10: X | K10: X | L10: X | M10: X | N10: X | O10: X | P10: X | Q10: X | R10: X | S10: V,C,E,D,A | T10: X | U10: V | V10: V,C,E,D,A | W10: V,C,E,D,A | X10: X | Y10: X | Z10: X | AA10: V,C,E,D,A | AB10: X | AC10: X
A11: Housekeeping Manager | B11: V | C11: X | D11: X | E11: V,C,E,D,A | F11: V,C,E,D,A | G11: X | H11: X | I11: V,C,E,D,A | J11: X | K11: X | L11: X | M11: X | N11: X | O11: V,C,E,D,A | P11: V,C,E,D,A | Q11: X | R11: X | S11: X | T11: X | U11: V | V11: X | W11: X | X11: X | Y11: X | Z11: X | AA11: X | AB11: X | AC11: X
A12: Housekeeping Attendant | B12: V | C12: X | D12: X | E12: V,C,E | F12: X | G12: X | H12: X | I12: V,C,E | J12: X | K12: X | L12: X | M12: X | N12: X | O12: X | P12: X | Q12: X | R12: X | S12: X | T12: X | U12: V | V12: X | W12: X | X12: X | Y12: X | Z12: X | AA12: X | AB12: X | AC12: X
A13: F&B Manager | B13: V | C13: X | D13: X | E13: X | F13: X | G13: X | H13: V,C,E,D,A | I13: X | J13: X | K13: X | L13: X | M13: X | N13: X | O13: V,C,E,D,A | P13: X | Q13: V,C,E,D,A | R13: V,C,E,D,A | S13: X | T13: X | U13: V,C,E,D,A | V13: X | W13: X | X13: X | Y13: X | Z13: X | AA13: X | AB13: X | AC13: X
A14: POS Cashier / Server | B14: V | C14: X | D14: X | E14: X | F14: X | G14: X | H14: V,C,E | I14: X | J14: X | K14: X | L14: X | M14: X | N14: X | O14: X | P14: X | Q14: V,C,E | R14: X | S14: X | T14: X | U14: V | V14: X | W14: X | X14: X | Y14: X | Z14: X | AA14: X | AB14: X | AC14: X
A15: Spa / Activities Manager | B15: V | C15: X | D15: X | E15: X | F15: X | G15: V,C,E,D,A | H15: X | I15: X | J15: V,C,E,D,A | K15: V,C,E,D,A | L15: X | M15: X | N15: X | O15: X | P15: V,C,E,D,A | Q15: V,C,E,D,A | R15: X | S15: X | T15: X | U15: V | V15: X | W15: X | X15: X | Y15: X | Z15: X | AA15: X | AB15: X | AC15: X
... A27: AI / Integration Admin | B27: V | C27: X | D27: X | E27: X | F27: X | G27: X | H27: X | I27: X | J27: X | K27: X | L27: X | M27: X | N27: X | O27: X | P27: X | Q27: X | R27: X | S27: X | T27: V,C,E,D,A | U27: V | V27: X | W27: X | X27: V,C,E,D,A | Y27: V,C,E,D,A | Z27: X | AA27: X | AB27: X | AC27: V,C,E,D,A

Sheet API & Data Mapping
A1: API, Data Entity & Integration Mapping
A3: Module | B3: Service / Bounded Context | C3: Core API Pattern | D3: Core Data Entities | E3: Domain Events | F3: External Integrations | G3: Security & Audit | H3: Implementation Status
A4: Overview | B4: Overview Service | C4: /api/v1/overview/* | D4: dashboard_snapshots, operational_metrics | E4: overview.created; overview.updated; overview.status_changed | F4: Internal event bus and notification service | G4: Tenant/property scope; RBAC; encryption; idempotency; audit correlation ID | H4: Not Started
A5: Front Desk | B5: Front Desk Service | C5: /api/v1/front-desk/* | D5: stays, room_assignments, folios, keys | E5: front-desk.created; front-desk.updated; front-desk.status_changed | F5: Internal event bus and notification service | G5: Tenant/property scope; RBAC; encryption; idempotency; audit correlation ID | H5: Not Started
A6: Reservations | B6: Reservations Service | C6: /api/v1/reservations/* | D6: reservations, reservation_guests, reservation_items, deposits | E6: reservations.created; reservations.updated; reservations.status_changed | F6: Internal event bus and notification service | G6: Tenant/property scope; RBAC; encryption; idempotency; audit correlation ID | H6: Not Started
A7: Housekeeping | B7: Housekeeping Service | C7: /api/v1/housekeeping/* | D7: housekeeping_tasks, room_status_logs, lost_found, linen_movements, minibar_postings | E7: housekeeping.created; housekeeping.updated; housekeeping.status_changed | F7: Internal event bus and notification service | G7: Tenant/property scope; RBAC; encryption; idempotency; audit correlation ID | H7: Not Started
A8: Property & Rooms | B8: Property & Rooms Service | C8: /api/v1/property-rooms/* | D8: properties, buildings, floors, room_types, rooms, amenities | E8: property-rooms.created; property-rooms.updated; property-rooms.status_changed | F8: Internal event bus and notification service | G8: Tenant/property scope; RBAC; encryption; idempotency; audit correlation ID | H8: Not Started
A9: Guest CRM | B9: Guest CRM Service | C9: /api/v1/guest-crm/* | D9: guests, guest_preferences, consents, documents, loyalty_accounts | E9: guest-crm.created; guest-crm.updated; guest-crm.status_changed | F9: Internal event bus and notification service | G9: Tenant/property scope; RBAC; encryption; idempotency; audit correlation ID | H9: Not Started
A10: Food & Beverage | B10: Food & Beverage Service | C10: /api/v1/food-beverage/* | D10: outlets, tables, menu_items, pos_orders, pos_bills, kitchen_tickets | E10: food-beverage.created; food-beverage.updated; food-beverage.status_changed | F10: Internal event bus and notification service | G10: Tenant/property scope; RBAC; encryption; idempotency; audit correlation ID | H10: Not Started
A11: Guest Services | B11: Guest Services Service | C11: /api/v1/guest-services/* | D11: service_requests, service_tasks, guest_notes | E11: guest-services.created; guest-services.updated; guest-services.status_changed | F11: Internal event bus and notification service | G11: Tenant/property scope; RBAC; encryption; idempotency; audit correlation ID | H11: Not Started
A12: Activities | B12: Activities Service | C12: /api/v1/activities/* | D12: activities, activity_slots, activity_bookings | E12: activities.created; activities.updated; activities.status_changed | F12: Internal event bus and notification service | G12: Tenant/property scope; RBAC; encryption; idempotency; audit correlation ID | H12: Not Started
A13: Spa | B13: Spa Service | C13: /api/v1/spa/* | D13: treatments, spa_resources, spa_appointments | E13: spa.created; spa.updated; spa.status_changed | F13: Internal event bus and notification service | G13: Tenant/property scope; RBAC; encryption; idempotency; audit correlation ID | H13: Not Started
A14: Events & Banquets | B14: Events & Banquets Service | C14: /api/v1/events-banquets/* | D14: event_leads, quotations, events, function_sheets | E14: events-banquets.created; events-banquets.updated; events-banquets.status_changed | F14: Internal event bus and notification service | G14: Tenant/property scope; RBAC; encryption; idempotency; audit correlation ID | H14: Not Started
... A31: Integrations | B31: Integrations Service | C31: /api/v1/integrations/* | D31: integrations, credentials, webhooks, sync_jobs | E31: integrations.created; integrations.updated; integrations.status_changed | F31: Webhooks, partner APIs and scheduled sync | G31: Tenant/property scope; RBAC; encryption; idempotency; audit correlation ID | H31: Not Started

Sheet Test & Acceptance
A1: Screen Test & Acceptance Tracker
A3: Test ID | B3: Screen ID | C3: Module | D3: Screen Name | E3: Test Scenario | F3: Precondition | G3: Test Steps | H3: Expected Result | I3: Test Type | J3: Severity | K3: Owner | L3: Status | M3: Defect / Remarks
A4: TC-001 | B4: SCR-001 | C4: Overview | D4: Operations Dashboard | E4: Complete primary Operations Dashboard workflow with valid data and verify one invalid/unauthorized path. | F4: Test property, role and dependent master data exist. | G4: 1. Sign in with authorized role. 2. Open screen. 3. Search/create/edit/process primary record. 4. Validate status and related screen. 5. Verify audit. | H4: Valid action succeeds once; invalid/conflicting action is blocked; related data is consistent; audit contains actor, timestamp and reason. | I4: Functional + RBAC + Integration | J4: Critical | L4: Not Run
